"{\"data\": [\"dbt compile \\\\\", \"  --vars '{\\\"env\\\": \\\"dev\\\", \\\"execution_date\\\": \\\"2023-03-27T08:27:00.755209\\\", \\\"event\\\": {}, \\\"pipeline_uuid\\\": \\\"dbt_transformation\\\", \\\"block_uuid\\\": \\\"polit/models/polit_models/dbt_threads\\\"}' \\\\\", \"  --select models/polit-models/dbt_threads.sql \\\\\", \"  --project-dir *****************************/dbt/polit \\\\\", \"  --profiles-dir *****************************/dbt/polit\", \"\", \"\\u001b[0m08:27:03  Running with dbt=1.4.0\", \"\\u001b[0m08:27:03  Unable to do partial parsing because config vars, config profile, or config target have changed\", \"\\u001b[0m08:27:04  Found 3 models, 4 tests, 0 snapshots, 0 analyses, 334 macros, 0 operations, 0 seed files, 0 sources, 0 exposures, 0 metrics\", \"\\u001b[0m08:27:04  \", \"\\u001b[0m08:27:05  Concurrency: 1 threads (target='dev')\", \"\\u001b[0m08:27:05  \", \"\\u001b[0m08:27:05  Done.\", \"WARNING:google.auth.compute_engine._metadata:Compute Engine Metadata server unavailable on attempt 1 of 3. Reason: [Errno 111] Connection refused\", \"WARNING:google.auth.compute_engine._metadata:Compute Engine Metadata server unavailable on attempt 2 of 3. Reason: [Errno 111] Connection refused\", \"WARNING:google.auth.compute_engine._metadata:Compute Engine Metadata server unavailable on attempt 3 of 3. Reason: [Errno 111] Connection refused\", \"WARNING:google.auth._default:Authentication failed using Compute Engine authentication due to unavailable metadata server.\", \"BigQuery initialized\", \"\\u2514\\u2500 Connecting to BigQuery warehouse...\"], \"error\": null, \"execution_state\": null, \"metadata\": null, \"msg_id\": \"cbfae115-b2adb70b878b7df9db0404df_7_23\", \"msg_type\": \"stream\", \"type\": \"text/plain\", \"block_type\": \"dbt\", \"pipeline_uuid\": null, \"uuid\": \"polit/models/polit_models/dbt_threads\"}"